<sdf version='1.7'>
  <world name='default'>
    <light name='sun' type='directional'>
      <cast_shadows>1</cast_shadows>
      <pose>0 0 10 0 -0 0</pose>
      <diffuse>0.8 0.8 0.8 1</diffuse>
      <specular>0.2 0.2 0.2 1</specular>
      <attenuation>
        <range>1000</range>
        <constant>0.9</constant>
        <linear>0.01</linear>
        <quadratic>0.001</quadratic>
      </attenuation>
      <direction>-0.5 0.1 -0.9</direction>
      <spot>
        <inner_angle>0</inner_angle>
        <outer_angle>0</outer_angle>
        <falloff>0</falloff>
      </spot>
    </light>
    <model name='ground_plane'>
      <static>1</static>
      <link name='link'>
        <collision name='collision'>
          <geometry>
            <plane>
              <normal>0 0 1</normal>
              <size>100 100</size>
            </plane>
          </geometry>
          <surface>
            <friction>
              <ode>
                <mu>10000</mu>
                <mu2>10200</mu2>
              </ode>
              <torsional>
                <ode/>
              </torsional>
            </friction>
            <contact>
              <ode/>
            </contact>
            <bounce/>
          </surface>
          <max_contacts>10</max_contacts>
        </collision>
        <visual name='visual'>
          <cast_shadows>0</cast_shadows>
          <geometry>
            <plane>
              <normal>0 0 1</normal>
              <size>100 100</size>
            </plane>
          </geometry>
          <material>
            <script>
              <uri>file://media/materials/scripts/gazebo.material</uri>
              <name>Gazebo/Grey</name>
            </script>
          </material>
        </visual>
        <self_collide>0</self_collide>
        <enable_wind>0</enable_wind>
        <kinematic>0</kinematic>
      </link>
    </model>
    <gravity>0 0 -9.8</gravity>
    <magnetic_field>6e-06 2.3e-05 -4.2e-05</magnetic_field>
    <atmosphere type='adiabatic'/>
    <physics type='ode'>
      <max_step_size>0.001</max_step_size>
      <real_time_factor>1</real_time_factor>
      <real_time_update_rate>1000</real_time_update_rate>
    </physics>
    <scene>
      <ambient>0.4 0.4 0.4 1</ambient>
      <background>0.7 0.7 0.7 1</background>
      <shadows>1</shadows>
    </scene>
    <audio>
      <device>default</device>
    </audio>
    <wind/>
    <spherical_coordinates>
      <surface_model>EARTH_WGS84</surface_model>
      <latitude_deg>0</latitude_deg>
      <longitude_deg>0</longitude_deg>
      <elevation>0</elevation>
      <heading_deg>0</heading_deg>
    </spherical_coordinates>
    <model name='vessel_slop'>
      <link name='base_link'>
        <inertial>
          <pose>0.023522 -0.021428 8.87457 0 -0 0</pose>
          <mass>3.66044e+07</mass>
          <inertia>
            <ixx>4.33424e+09</ixx>
            <ixy>-4.28811e+06</ixy>
            <ixz>-2.24198e+06</ixz>
            <iyy>9.29063e+08</iyy>
            <iyz>1.95924e+06</iyz>
            <izz>4.00963e+09</izz>
          </inertia>
        </inertial>
        <collision name='base_link_collision'>
          <pose>0 0 0 0 -0 0</pose>
          <geometry>
            <mesh>
              <scale>0.001 0.001 0.001</scale>
              <uri>file:///home/roey/nakai_ws/install/vessel_slop_description/share/vessel_slop_description/meshes/base_link.stl</uri>
            </mesh>
          </geometry>
          <surface>
            <contact>
              <ode/>
            </contact>
            <friction>
              <ode>
                <mu>1200.2</mu>
                <mu2>2000.2</mu2>
              </ode>
              <torsional>
                <ode/>
              </torsional>
            </friction>
            <bounce/>
          </surface>
          <max_contacts>10</max_contacts>
        </collision>
        <visual name='base_link_visual'>
          <pose>0 0 0 0 -0 0</pose>
          <geometry>
            <mesh>
              <scale>0.001 0.001 0.001</scale>
              <uri>file:///home/roey/nakai_ws/install/vessel_slop_description/share/vessel_slop_description/meshes/base_link.stl</uri>
            </mesh>
          </geometry>
          <material>
            <script>
              <uri>file://media/materials/scripts/gazebo.material</uri>
              <name>Gazebo/Green</name>
            </script>
            <texture>
              <image>ship_hull.png</image>
            </texture>
          </material>
        </visual>
        <self_collide>1</self_collide>
        <gravity>1</gravity>
        <enable_wind>0</enable_wind>
        <kinematic>0</kinematic>
      </link>
      <static>0</static>
      <plugin name='control' filename='libgazebo_ros_control.so'/>
      <pose>0 0 0 0 -0 0</pose>
    </model>
    <state world_name='default'>
      <sim_time>68 600000000</sim_time>
      <real_time>70 134117032</real_time>
      <wall_time>1734118938 580674287</wall_time>
      <iterations>68600</iterations>
      <model name='ground_plane'>
        <pose>0 0 0 0 -0 0</pose>
        <scale>1 1 1</scale>
        <link name='link'>
          <pose>0 0 0 0 -0 0</pose>
          <velocity>0 0 0 0 -0 0</velocity>
          <acceleration>0 0 0 0 -0 0</acceleration>
          <wrench>0 0 0 0 -0 0</wrench>
        </link>
      </model>
      <model name='my_robot'>
        <pose>15.7422 2.63566 14.0832 0.982685 1.25452 -2.19772</pose>
        <scale>1 1 1</scale>
        <link name='base_footprint'>
          <pose>15.7422 2.63566 14.0832 0.982685 1.25452 -2.19772</pose>
          <velocity>-0.013907 -0.008273 -0.039983 0.001797 0.000766 0.004235</velocity>
          <acceleration>-2.41606 -2.41814 11.2814 0.238571 1.49242 -0.339167</acceleration>
          <wrench>-25.127 -25.1486 117.327 0 -0 0</wrench>
        </link>
        <link name='left_rear_wheel_link'>
          <pose>15.5638 2.65763 14.3484 2.89131 0.800651 -1.81464</pose>
          <velocity>-0.013668 -0.008824 -0.042907 0.000175 0.009283 0.011484</velocity>
          <acceleration>-1.38281 10.5337 13.2689 1.77645 -1.33524 -2.76731</acceleration>
          <wrench>-1.38281 10.5337 13.2689 0 -0 0</wrench>
        </link>
        <link name='left_wheel_link'>
          <pose>15.4817 2.5443 13.9207 2.94968 -0.439575 -1.55021</pose>
          <velocity>-0.013799 -0.011009 -0.043739 -0.009697 0.00818 0.013271</velocity>
          <acceleration>-0.111389 -0.707677 3.45613 2.56819 0.086595 -0.452549</acceleration>
          <wrench>-0.111389 -0.707677 3.45613 0 -0 0</wrench>
        </link>
        <link name='right_rear_wheel_link'>
          <pose>16.0013 2.63045 14.2716 2.96542 0.177414 -1.66427</pose>
          <velocity>-0.013537 -0.009778 -0.042996 -0.006073 0.006417 0.0094</velocity>
          <acceleration>-1.63398 -6.80837 3.76229 -2.97327 -0.415262 2.36455</acceleration>
          <wrench>-1.63398 -6.80837 3.76229 0 -0 0</wrench>
        </link>
        <link name='right_wheel_link'>
          <pose>15.9192 2.51713 13.844 2.96669 -0.133643 -1.60934</pose>
          <velocity>-0.013992 -0.009416 -0.045244 -0.024795 0.006937 0.017892</velocity>
          <acceleration>-1.10187 -5.86738 3.46565 2.48025 0.025019 -2.79855</acceleration>
          <wrench>-1.10187 -5.86738 3.46565 0 -0 0</wrench>
        </link>
      </model>
      <model name='vessel_slop'>
        <pose>-0.021723 -3.55487 -0.000413 -8e-06 -8.1e-05 1.55571</pose>
        <scale>1 1 1</scale>
        <link name='base_link'>
          <pose>-0.021723 -3.55487 -0.000413 -8e-06 -8.1e-05 1.55571</pose>
          <velocity>0 -0 -0.06067 0.000734 -0.000872 0</velocity>
          <acceleration>-0.048559 1.39637 -0.250819 -0.733804 0.008407 -0.000281</acceleration>
          <wrench>-1.77746e+06 5.11135e+07 -9.18107e+06 0 -0 0</wrench>
        </link>
      </model>
      <light name='sun'>
        <pose>0 0 10 0 -0 0</pose>
      </light>
    </state>
    <gui fullscreen='0'>
      <camera name='user_camera'>
        <pose>20.2789 14.6495 15.7591 0 0.367642 -2.11499</pose>
        <view_controller>orbit</view_controller>
        <projection_type>perspective</projection_type>
      </camera>
    </gui>
    <model name='my_robot'>
      <link name='base_footprint'>
        <inertial>
          <pose>0.015069 0.002019 -0.189904 0 -0 0</pose>
          <mass>10.4</mass>
          <inertia>
            <ixx>2.26998</ixx>
            <ixy>-0.00823145</ixy>
            <ixz>-0.0297612</ixz>
            <iyy>2.1321</iyy>
            <iyz>-0.00398798</iyz>
            <izz>0.398665</izz>
          </inertia>
        </inertial>
        <collision name='base_footprint_fixed_joint_lump__base_link_collision'>
          <pose>0 0 0 0 -0 0</pose>
          <geometry>
            <box>
              <size>0.8 0.2 0.4</size>
            </box>
          </geometry>
          <surface>
            <contact>
              <ode/>
            </contact>
            <friction>
              <ode/>
              <torsional>
                <ode/>
              </torsional>
            </friction>
            <bounce/>
          </surface>
          <max_contacts>10</max_contacts>
        </collision>
        <collision name='base_footprint_fixed_joint_lump__camera_link_collision_1'>
          <pose>0.352174 0 -0 1.5708 -0 0.25</pose>
          <geometry>
            <box>
              <size>0.01 0.1 0.05</size>
            </box>
          </geometry>
          <surface>
            <contact>
              <ode/>
            </contact>
            <friction>
              <ode/>
              <torsional>
                <ode/>
              </torsional>
            </friction>
            <bounce/>
          </surface>
          <max_contacts>10</max_contacts>
        </collision>
        <collision name='base_footprint_fixed_joint_lump__imu_link_collision_2'>
          <pose>0 0 0.03 0 -0 0</pose>
          <geometry>
            <box>
              <size>0.03 0.05 0.01</size>
            </box>
          </geometry>
          <surface>
            <contact>
              <ode/>
            </contact>
            <friction>
              <ode/>
              <torsional>
                <ode/>
              </torsional>
            </friction>
            <bounce/>
          </surface>
          <max_contacts>10</max_contacts>
        </collision>
        <collision name='base_footprint_fixed_joint_lump__sensor2_link_collision_3'>
          <pose>0.405 0.07 -0.13 1.5708 0.35 0.1</pose>
          <geometry>
            <box>
              <size>0.01 0.1 0.05</size>
            </box>
          </geometry>
          <surface>
            <contact>
              <ode/>
            </contact>
            <friction>
              <ode/>
              <torsional>
                <ode/>
              </torsional>
            </friction>
            <bounce/>
          </surface>
          <max_contacts>10</max_contacts>
        </collision>
        <collision name='base_footprint_fixed_joint_lump__sensor3_link_collision_4'>
          <pose>0.405 0.07 0.13 1.5708 -0.35 0.1</pose>
          <geometry>
            <box>
              <size>0.01 0.1 0.05</size>
            </box>
          </geometry>
          <surface>
            <contact>
              <ode/>
            </contact>
            <friction>
              <ode/>
              <torsional>
                <ode/>
              </torsional>
            </friction>
            <bounce/>
          </surface>
          <max_contacts>10</max_contacts>
        </collision>
        <collision name='base_footprint_fixed_joint_lump__sensor1_link_collision_5'>
          <pose>0.405 0.07 -0 1.5708 -0 0.1</pose>
          <geometry>
            <box>
              <size>0.01 0.1 0.05</size>
            </box>
          </geometry>
          <surface>
            <contact>
              <ode/>
            </contact>
            <friction>
              <ode/>
              <torsional>
                <ode/>
              </torsional>
            </friction>
            <bounce/>
          </surface>
          <max_contacts>10</max_contacts>
        </collision>
        <visual name='base_footprint_fixed_joint_lump__base_link_visual'>
          <pose>0 0 0 0 -0 0</pose>
          <geometry>
            <box>
              <size>0.8 0.2 0.4</size>
            </box>
          </geometry>
          <material>
            <script>
              <name>Gazebo/Red</name>
              <uri>file://media/materials/scripts/gazebo.material</uri>
            </script>
          </material>
        </visual>
        <visual name='base_footprint_fixed_joint_lump__camera_link_visual_1'>
          <pose>0.352174 0 -0 1.5708 -0 0.25</pose>
          <geometry>
            <box>
              <size>0.01 0.1 0.05</size>
            </box>
          </geometry>
          <material>
            <script>
              <name>Gazebo/Red</name>
              <uri>file://media/materials/scripts/gazebo.material</uri>
            </script>
          </material>
        </visual>
        <visual name='base_footprint_fixed_joint_lump__imu_link_visual_2'>
          <pose>0 0 0.03 0 -0 0</pose>
          <geometry>
            <box>
              <size>0.03 0.05 0.01</size>
            </box>
          </geometry>
        </visual>
        <visual name='base_footprint_fixed_joint_lump__sensor2_link_visual_3'>
          <pose>0.405 0.07 -0.13 1.5708 0.35 0.1</pose>
          <geometry>
            <box>
              <size>0.01 0.1 0.05</size>
            </box>
          </geometry>
        </visual>
        <visual name='base_footprint_fixed_joint_lump__sensor3_link_visual_4'>
          <pose>0.405 0.07 0.13 1.5708 -0.35 0.1</pose>
          <geometry>
            <box>
              <size>0.01 0.1 0.05</size>
            </box>
          </geometry>
        </visual>
        <visual name='base_footprint_fixed_joint_lump__sensor1_link_visual_5'>
          <pose>0.405 0.07 -0 1.5708 -0 0.1</pose>
          <geometry>
            <box>
              <size>0.01 0.1 0.05</size>
            </box>
          </geometry>
        </visual>
        <sensor name='camera_sensor' type='camera'>
          <visualize>1</visualize>
          <update_rate>20</update_rate>
          <plugin name='camera_controller' filename='libgazebo_ros_camera.so'>
            <frame_name>camera_link_optical</frame_name>
          </plugin>
          <pose>0.352174 0 -0 1.5708 -0 0.25</pose>
          <camera>
            <horizontal_fov>1.047</horizontal_fov>
            <image>
              <width>320</width>
              <height>240</height>
            </image>
            <clip>
              <near>0.1</near>
              <far>100</far>
            </clip>
          </camera>
        </sensor>
        <gravity>1</gravity>
        <sensor name='imu' type='imu'>
          <plugin name='imu_plugin' filename='libgazebo_ros_imu_sensor.so'>
            <ros>
              <remapping>~/out:=/data/imu</remapping>
            </ros>
            <initial_orientation_as_reference>0</initial_orientation_as_reference>
          </plugin>
          <always_on>1</always_on>
          <update_rate>100</update_rate>
          <imu>
            <angular_velocity>
              <x>
                <noise type='gaussian'>
                  <mean>0</mean>
                  <stddev>1.74533e-05</stddev>
                  <bias_mean>0</bias_mean>
                  <bias_stddev>0</bias_stddev>
                </noise>
              </x>
              <y>
                <noise type='gaussian'>
                  <mean>0</mean>
                  <stddev>1.74533e-05</stddev>
                  <bias_mean>0</bias_mean>
                  <bias_stddev>0</bias_stddev>
                </noise>
              </y>
              <z>
                <noise type='gaussian'>
                  <mean>0</mean>
                  <stddev>1.74533e-05</stddev>
                  <bias_mean>0</bias_mean>
                  <bias_stddev>0</bias_stddev>
                </noise>
              </z>
            </angular_velocity>
            <linear_acceleration>
              <x>
                <noise type='gaussian'>
                  <mean>0</mean>
                  <stddev>0.017</stddev>
                  <bias_mean>0.1</bias_mean>
                  <bias_stddev>0.001</bias_stddev>
                </noise>
              </x>
              <y>
                <noise type='gaussian'>
                  <mean>0</mean>
                  <stddev>0.017</stddev>
                  <bias_mean>0.1</bias_mean>
                  <bias_stddev>0.001</bias_stddev>
                </noise>
              </y>
              <z>
                <noise type='gaussian'>
                  <mean>0</mean>
                  <stddev>0.017</stddev>
                  <bias_mean>0.1</bias_mean>
                  <bias_stddev>0.001</bias_stddev>
                </noise>
              </z>
            </linear_acceleration>
          </imu>
          <pose>0 0 0.1 0 -0 0</pose>
        </sensor>
        <sensor name='sensor_ultrasound2' type='ray'>
          <always_on>1</always_on>
          <visualize>1</visualize>
          <update_rate>10</update_rate>
          <ray>
            <scan>
              <horizontal>
                <samples>5</samples>
                <resolution>1</resolution>
                <min_angle>-0.08</min_angle>
                <max_angle>0.08</max_angle>
              </horizontal>
              <vertical>
                <samples>1</samples>
                <min_angle>0</min_angle>
                <max_angle>0</max_angle>
              </vertical>
            </scan>
            <range>
              <min>0.2</min>
              <max>2</max>
              <resolution>0.01</resolution>
            </range>
          </ray>
          <plugin name='sensor_controller2' filename='libgazebo_ros_ray_sensor.so'>
            <ros>
              <remapping>~/out:=/range/raw</remapping>
            </ros>
            <radiation_type>ultrasound</radiation_type>
            <output_type>sensor_msgs/Range</output_type>
            <frame_name>base_link</frame_name>
          </plugin>
          <pose>0.405 0.07 -0.13 1.5708 0.35 0.1</pose>
        </sensor>
        <sensor name='sensor_ultrasound3' type='ray'>
          <always_on>1</always_on>
          <visualize>1</visualize>
          <update_rate>10</update_rate>
          <ray>
            <scan>
              <horizontal>
                <samples>5</samples>
                <resolution>1</resolution>
                <min_angle>-0.08</min_angle>
                <max_angle>0.08</max_angle>
              </horizontal>
              <vertical>
                <samples>1</samples>
                <min_angle>0</min_angle>
                <max_angle>0</max_angle>
              </vertical>
            </scan>
            <range>
              <min>0.2</min>
              <max>2</max>
              <resolution>0.01</resolution>
            </range>
          </ray>
          <plugin name='sensor_controller3' filename='libgazebo_ros_ray_sensor.so'>
            <ros>
              <remapping>~/out:=/range/raw</remapping>
            </ros>
            <radiation_type>ultrasound</radiation_type>
            <output_type>sensor_msgs/Range</output_type>
            <frame_name>base_link</frame_name>
          </plugin>
          <pose>0.405 0.07 0.13 1.5708 -0.35 0.1</pose>
        </sensor>
        <sensor name='sensor_ultrasound1' type='ray'>
          <always_on>1</always_on>
          <visualize>1</visualize>
          <update_rate>10</update_rate>
          <ray>
            <scan>
              <horizontal>
                <samples>5</samples>
                <resolution>1</resolution>
                <min_angle>-0.08</min_angle>
                <max_angle>0.08</max_angle>
              </horizontal>
              <vertical>
                <samples>1</samples>
                <min_angle>0</min_angle>
                <max_angle>0</max_angle>
              </vertical>
            </scan>
            <range>
              <min>0.2</min>
              <max>2</max>
              <resolution>0.01</resolution>
            </range>
          </ray>
          <plugin name='sensor_controller1' filename='libgazebo_ros_ray_sensor.so'>
            <ros>
              <remapping>~/out:=/range/raw</remapping>
            </ros>
            <radiation_type>ultrasound</radiation_type>
            <output_type>sensor_msgs/Range</output_type>
            <frame_name>base_link</frame_name>
          </plugin>
          <pose>0.405 0.07 -0 1.5708 -0 0.1</pose>
        </sensor>
        <self_collide>0</self_collide>
        <enable_wind>0</enable_wind>
        <kinematic>0</kinematic>
      </link>
      <joint name='base_left_rear_wheel_joint' type='revolute'>
        <pose relative_to='base_footprint'>-0.225 0.05 0.2225 1.5708 -0 0</pose>
        <parent>base_footprint</parent>
        <child>left_rear_wheel_link</child>
        <axis>
          <xyz>0 1 0</xyz>
          <limit>
            <lower>-1e+16</lower>
            <upper>1e+16</upper>
          </limit>
          <dynamics>
            <spring_reference>0</spring_reference>
            <spring_stiffness>0</spring_stiffness>
          </dynamics>
        </axis>
      </joint>
      <link name='left_rear_wheel_link'>
        <pose relative_to='base_left_rear_wheel_joint'>0 0 0 0 -0 0</pose>
        <inertial>
          <pose>0 0 0 1.5708 -0 0</pose>
          <mass>1</mass>
          <inertia>
            <ixx>0.0108333</ixx>
            <ixy>0</ixy>
            <ixz>0</ixz>
            <iyy>0.0108333</iyy>
            <iyz>0</iyz>
            <izz>0.02</izz>
          </inertia>
        </inertial>
        <collision name='left_rear_wheel_link_collision'>
          <pose>0 0 0 1.5708 -0 0</pose>
          <geometry>
            <cylinder>
              <length>0.05</length>
              <radius>0.1</radius>
            </cylinder>
          </geometry>
          <surface>
            <contact>
              <ode/>
            </contact>
            <friction>
              <ode/>
              <torsional>
                <ode/>
              </torsional>
            </friction>
            <bounce/>
          </surface>
          <max_contacts>10</max_contacts>
        </collision>
        <visual name='left_rear_wheel_link_visual'>
          <pose>0 0 0 1.5708 -0 0</pose>
          <geometry>
            <cylinder>
              <length>0.05</length>
              <radius>0.1</radius>
            </cylinder>
          </geometry>
          <material>
            <script>
              <name>Gazebo/Grey</name>
              <uri>file://media/materials/scripts/gazebo.material</uri>
            </script>
          </material>
        </visual>
        <self_collide>0</self_collide>
        <enable_wind>0</enable_wind>
        <kinematic>0</kinematic>
        <surface>
          <friction>
            <ode>
              <mu>100</mu>
              <mu2>50</mu2>
            </ode>
          </friction>
        </surface>
      </link>
      <joint name='base_left_wheel_joint' type='revolute'>
        <pose relative_to='base_footprint'>0.225 0.05 0.2225 1.5708 -0 0</pose>
        <parent>base_footprint</parent>
        <child>left_wheel_link</child>
        <axis>
          <xyz>0 1 0</xyz>
          <limit>
            <lower>-1e+16</lower>
            <upper>1e+16</upper>
          </limit>
          <dynamics>
            <spring_reference>0</spring_reference>
            <spring_stiffness>0</spring_stiffness>
          </dynamics>
        </axis>
      </joint>
      <link name='left_wheel_link'>
        <pose relative_to='base_left_wheel_joint'>0 0 0 0 -0 0</pose>
        <inertial>
          <pose>0 0 0 1.5708 -0 0</pose>
          <mass>1</mass>
          <inertia>
            <ixx>0.0108333</ixx>
            <ixy>0</ixy>
            <ixz>0</ixz>
            <iyy>0.0108333</iyy>
            <iyz>0</iyz>
            <izz>0.02</izz>
          </inertia>
        </inertial>
        <collision name='left_wheel_link_collision'>
          <pose>0 0 0 1.5708 -0 0</pose>
          <geometry>
            <cylinder>
              <length>0.05</length>
              <radius>0.1</radius>
            </cylinder>
          </geometry>
          <surface>
            <contact>
              <ode/>
            </contact>
            <friction>
              <ode/>
              <torsional>
                <ode/>
              </torsional>
            </friction>
            <bounce/>
          </surface>
          <max_contacts>10</max_contacts>
        </collision>
        <visual name='left_wheel_link_visual'>
          <pose>0 0 0 1.5708 -0 0</pose>
          <geometry>
            <cylinder>
              <length>0.05</length>
              <radius>0.1</radius>
            </cylinder>
          </geometry>
          <material>
            <script>
              <name>Gazebo/Grey</name>
              <uri>file://media/materials/scripts/gazebo.material</uri>
            </script>
          </material>
        </visual>
        <self_collide>0</self_collide>
        <enable_wind>0</enable_wind>
        <kinematic>0</kinematic>
        <surface>
          <friction>
            <ode>
              <mu>100</mu>
              <mu2>50</mu2>
            </ode>
          </friction>
        </surface>
      </link>
      <joint name='base_right_rear_wheel_joint' type='revolute'>
        <pose relative_to='base_footprint'>-0.225 0.05 -0.2225 1.5708 -0 0</pose>
        <parent>base_footprint</parent>
        <child>right_rear_wheel_link</child>
        <axis>
          <xyz>0 1 0</xyz>
          <limit>
            <lower>-1e+16</lower>
            <upper>1e+16</upper>
          </limit>
          <dynamics>
            <spring_reference>0</spring_reference>
            <spring_stiffness>0</spring_stiffness>
          </dynamics>
        </axis>
      </joint>
      <link name='right_rear_wheel_link'>
        <pose relative_to='base_right_rear_wheel_joint'>0 0 0 0 -0 0</pose>
        <inertial>
          <pose>0 0 0 1.5708 -0 0</pose>
          <mass>1</mass>
          <inertia>
            <ixx>0.0108333</ixx>
            <ixy>0</ixy>
            <ixz>0</ixz>
            <iyy>0.0108333</iyy>
            <iyz>0</iyz>
            <izz>0.02</izz>
          </inertia>
        </inertial>
        <collision name='right_rear_wheel_link_collision'>
          <pose>0 0 0 1.5708 -0 0</pose>
          <geometry>
            <cylinder>
              <length>0.05</length>
              <radius>0.1</radius>
            </cylinder>
          </geometry>
          <surface>
            <contact>
              <ode/>
            </contact>
            <friction>
              <ode/>
              <torsional>
                <ode/>
              </torsional>
            </friction>
            <bounce/>
          </surface>
          <max_contacts>10</max_contacts>
        </collision>
        <visual name='right_rear_wheel_link_visual'>
          <pose>0 0 0 1.5708 -0 0</pose>
          <geometry>
            <cylinder>
              <length>0.05</length>
              <radius>0.1</radius>
            </cylinder>
          </geometry>
          <material>
            <script>
              <name>Gazebo/Grey</name>
              <uri>file://media/materials/scripts/gazebo.material</uri>
            </script>
          </material>
        </visual>
        <self_collide>0</self_collide>
        <enable_wind>0</enable_wind>
        <kinematic>0</kinematic>
        <surface>
          <friction>
            <ode>
              <mu>100</mu>
              <mu2>50</mu2>
            </ode>
          </friction>
        </surface>
      </link>
      <joint name='base_right_wheel_joint' type='revolute'>
        <pose relative_to='base_footprint'>0.225 0.05 -0.2225 1.5708 -0 0</pose>
        <parent>base_footprint</parent>
        <child>right_wheel_link</child>
        <axis>
          <xyz>0 1 0</xyz>
          <limit>
            <lower>-1e+16</lower>
            <upper>1e+16</upper>
          </limit>
          <dynamics>
            <spring_reference>0</spring_reference>
            <spring_stiffness>0</spring_stiffness>
          </dynamics>
        </axis>
      </joint>
      <link name='right_wheel_link'>
        <pose relative_to='base_right_wheel_joint'>0 0 0 0 -0 0</pose>
        <inertial>
          <pose>0 0 0 1.5708 -0 0</pose>
          <mass>1</mass>
          <inertia>
            <ixx>0.0108333</ixx>
            <ixy>0</ixy>
            <ixz>0</ixz>
            <iyy>0.0108333</iyy>
            <iyz>0</iyz>
            <izz>0.02</izz>
          </inertia>
        </inertial>
        <collision name='right_wheel_link_collision'>
          <pose>0 0 0 1.5708 -0 0</pose>
          <geometry>
            <cylinder>
              <length>0.05</length>
              <radius>0.1</radius>
            </cylinder>
          </geometry>
          <surface>
            <contact>
              <ode/>
            </contact>
            <friction>
              <ode/>
              <torsional>
                <ode/>
              </torsional>
            </friction>
            <bounce/>
          </surface>
          <max_contacts>10</max_contacts>
        </collision>
        <visual name='right_wheel_link_visual'>
          <pose>0 0 0 1.5708 -0 0</pose>
          <geometry>
            <cylinder>
              <length>0.05</length>
              <radius>0.1</radius>
            </cylinder>
          </geometry>
          <material>
            <script>
              <name>Gazebo/Grey</name>
              <uri>file://media/materials/scripts/gazebo.material</uri>
            </script>
          </material>
        </visual>
        <self_collide>0</self_collide>
        <enable_wind>0</enable_wind>
        <kinematic>0</kinematic>
        <surface>
          <friction>
            <ode>
              <mu>100</mu>
              <mu2>50</mu2>
            </ode>
          </friction>
        </surface>
      </link>
      <plugin name='diff_drive' filename='libgazebo_ros_diff_drive.so'>
        <update_rate>10.0</update_rate>
        <num_wheel_pairs>2</num_wheel_pairs>
        <right_joint>base_right_wheel_joint</right_joint>
        <left_joint>base_left_wheel_joint</left_joint>
        <right_joint>base_right_rear_wheel_joint</right_joint>
        <left_joint>base_left_rear_wheel_joint</left_joint>
        <wheel_separation>0.445</wheel_separation>
        <wheel_diameter>0.2</wheel_diameter>
        <wheel_separation>0.445</wheel_separation>
        <wheel_diameter>0.2</wheel_diameter>
        <max_wheel_torque>200</max_wheel_torque>
        <max_wheel_acceleration>100.0</max_wheel_acceleration>
        <max_wheel_torque>200</max_wheel_torque>
        <max_wheel_acceleration>100.0</max_wheel_acceleration>
        <publish_odom>1</publish_odom>
        <publish_odom_tf>0</publish_odom_tf>
        <publish_wheel_tf>0</publish_wheel_tf>
        <odometry_frame>odom</odometry_frame>
        <robot_base_frame>base_footprint</robot_base_frame>
      </plugin>
      <plugin name='force1_plugin' filename='libgazebo_ros_force.so'>
        <ros>
          <namespace>/my_robot_namespace</namespace>
          <remapping>gazebo_ros_force:=/apply_force</remapping>
        </ros>
        <link_name>right_rear_wheel_link</link_name>
        <force_frame>world</force_frame>
      </plugin>
      <plugin name='force2_plugin' filename='libgazebo_ros_force.so'>
        <ros>
          <namespace>/my_robot_namespace</namespace>
          <remapping>gazebo_ros_force:=/apply_force</remapping>
        </ros>
        <link_name>left_wheel_link</link_name>
        <force_frame>world</force_frame>
      </plugin>
      <plugin name='force3_plugin' filename='libgazebo_ros_force.so'>
        <ros>
          <namespace>/my_robot_namespace</namespace>
          <remapping>gazebo_ros_force:=/apply_force</remapping>
        </ros>
        <link_name>left_rear_wheel_link</link_name>
        <force_frame>world</force_frame>
      </plugin>
      <plugin name='force4_plugin' filename='libgazebo_ros_force.so'>
        <ros>
          <namespace>/my_robot_namespace</namespace>
          <remapping>gazebo_ros_force:=/apply_force</remapping>
        </ros>
        <link_name>right_wheel_link</link_name>
        <force_frame>world</force_frame>
      </plugin>
      <static>0</static>
      <plugin name='joint_state_publisher' filename='libgazebo_ros_joint_state_publisher.so'>
        <jointName>base_right_wheel_joint</jointName>
        <jointName>base_left_wheel_joint</jointName>
        <jointName>base_right_rear_wheel_joint</jointName>
        <jointName>base_left_rear_wheel_joint</jointName>
        <jointName>base_joint</jointName>
        <jointName>base_imu_joint</jointName>
      </plugin>
      <pose>0 0 4 -1.57 0 0</pose>
    </model>
  </world>
</sdf>
